INFO:     Started server process [7399]
INFO:     Waiting for application startup.
INFO:     Application startup complete.
INFO:     Uvicorn running on http://0.0.0.0:8001 (Press CTRL+C to quit)
INFO:     127.0.0.1:52602 - "GET / HTTP/1.1" 200 OK
ERROR:    Exception in ASGI application
Traceback (most recent call last):
  File "/Users/rohithbollineni/Library/Python/3.9/lib/python/site-packages/uvicorn/protocols/http/h11_impl.py", line 408, in run_asgi
    result = await app(  # type: ignore[func-returns-value]
  File "/Users/rohithbollineni/Library/Python/3.9/lib/python/site-packages/uvicorn/middleware/proxy_headers.py", line 84, in __call__
    return await self.app(scope, receive, send)
  File "/Users/rohithbollineni/Library/Python/3.9/lib/python/site-packages/fastapi/applications.py", line 1054, in __call__
    await super().__call__(scope, receive, send)
  File "/Users/rohithbollineni/Library/Python/3.9/lib/python/site-packages/starlette/applications.py", line 123, in __call__
    await self.middleware_stack(scope, receive, send)
  File "/Users/rohithbollineni/Library/Python/3.9/lib/python/site-packages/starlette/middleware/errors.py", line 186, in __call__
    raise exc
  File "/Users/rohithbollineni/Library/Python/3.9/lib/python/site-packages/starlette/middleware/errors.py", line 164, in __call__
    await self.app(scope, receive, _send)
  File "/Users/rohithbollineni/Library/Python/3.9/lib/python/site-packages/starlette/middleware/cors.py", line 85, in __call__
    await self.app(scope, receive, send)
  File "/Users/rohithbollineni/Library/Python/3.9/lib/python/site-packages/starlette/middleware/exceptions.py", line 65, in __call__
    await wrap_app_handling_exceptions(self.app, conn)(scope, receive, send)
  File "/Users/rohithbollineni/Library/Python/3.9/lib/python/site-packages/starlette/_exception_handler.py", line 64, in wrapped_app
    raise exc
  File "/Users/rohithbollineni/Library/Python/3.9/lib/python/site-packages/starlette/_exception_handler.py", line 53, in wrapped_app
    await app(scope, receive, sender)
  File "/Users/rohithbollineni/Library/Python/3.9/lib/python/site-packages/starlette/routing.py", line 756, in __call__
    await self.middleware_stack(scope, receive, send)
  File "/Users/rohithbollineni/Library/Python/3.9/lib/python/site-packages/starlette/routing.py", line 776, in app
    await route.handle(scope, receive, send)
  File "/Users/rohithbollineni/Library/Python/3.9/lib/python/site-packages/starlette/routing.py", line 297, in handle
    await self.app(scope, receive, send)
  File "/Users/rohithbollineni/Library/Python/3.9/lib/python/site-packages/starlette/routing.py", line 77, in app
    await wrap_app_handling_exceptions(app, request)(scope, receive, send)
  File "/Users/rohithbollineni/Library/Python/3.9/lib/python/site-packages/starlette/_exception_handler.py", line 64, in wrapped_app
    raise exc
  File "/Users/rohithbollineni/Library/Python/3.9/lib/python/site-packages/starlette/_exception_handler.py", line 53, in wrapped_app
    await app(scope, receive, sender)
  File "/Users/rohithbollineni/Library/Python/3.9/lib/python/site-packages/starlette/routing.py", line 72, in app
    response = await func(request)
  File "/Users/rohithbollineni/Library/Python/3.9/lib/python/site-packages/fastapi/routing.py", line 278, in app
    raw_response = await run_endpoint_function(
  File "/Users/rohithbollineni/Library/Python/3.9/lib/python/site-packages/fastapi/routing.py", line 191, in run_endpoint_function
    return await dependant.call(**values)
  File "/Users/rohithbollineni/Downloads/Marshalats/backend/server.py", line 455, in register_user
    existing_user = await db.users.find_one({
  File "/Library/Developer/CommandLineTools/Library/Frameworks/Python3.framework/Versions/3.9/lib/python3.9/concurrent/futures/thread.py", line 52, in run
    result = self.fn(*self.args, **self.kwargs)
  File "/Users/rohithbollineni/Library/Python/3.9/lib/python/site-packages/pymongo/collection.py", line 1508, in find_one
    for result in cursor.limit(-1):
  File "/Users/rohithbollineni/Library/Python/3.9/lib/python/site-packages/pymongo/cursor.py", line 1262, in next
    if len(self.__data) or self._refresh():
  File "/Users/rohithbollineni/Library/Python/3.9/lib/python/site-packages/pymongo/cursor.py", line 1153, in _refresh
    self.__session = self.__collection.database.client._ensure_session()
  File "/Users/rohithbollineni/Library/Python/3.9/lib/python/site-packages/pymongo/mongo_client.py", line 1868, in _ensure_session
    return self.__start_session(True, causal_consistency=False)
  File "/Users/rohithbollineni/Library/Python/3.9/lib/python/site-packages/pymongo/mongo_client.py", line 1811, in __start_session
    self._topology._check_implicit_session_support()
  File "/Users/rohithbollineni/Library/Python/3.9/lib/python/site-packages/pymongo/topology.py", line 583, in _check_implicit_session_support
    self._check_session_support()
  File "/Users/rohithbollineni/Library/Python/3.9/lib/python/site-packages/pymongo/topology.py", line 599, in _check_session_support
    self._select_servers_loop(
  File "/Users/rohithbollineni/Library/Python/3.9/lib/python/site-packages/pymongo/topology.py", line 269, in _select_servers_loop
    raise ServerSelectionTimeoutError(
pymongo.errors.ServerSelectionTimeoutError: localhost:27017: [Errno 61] Connection refused, Timeout: 30s, Topology Description: <TopologyDescription id: 68b415f3e399609350ce5040, topology_type: Unknown, servers: [<ServerDescription ('localhost', 27017) server_type: Unknown, rtt: None, error=AutoReconnect('localhost:27017: [Errno 61] Connection refused')>]>
INFO:     127.0.0.1:52674 - "GET / HTTP/1.1" 200 OK
ERROR:    Exception in ASGI application
Traceback (most recent call last):
  File "/Users/rohithbollineni/Library/Python/3.9/lib/python/site-packages/uvicorn/protocols/http/h11_impl.py", line 408, in run_asgi
    result = await app(  # type: ignore[func-returns-value]
  File "/Users/rohithbollineni/Library/Python/3.9/lib/python/site-packages/uvicorn/middleware/proxy_headers.py", line 84, in __call__
    return await self.app(scope, receive, send)
  File "/Users/rohithbollineni/Library/Python/3.9/lib/python/site-packages/fastapi/applications.py", line 1054, in __call__
    await super().__call__(scope, receive, send)
  File "/Users/rohithbollineni/Library/Python/3.9/lib/python/site-packages/starlette/applications.py", line 123, in __call__
    await self.middleware_stack(scope, receive, send)
  File "/Users/rohithbollineni/Library/Python/3.9/lib/python/site-packages/starlette/middleware/errors.py", line 186, in __call__
    raise exc
  File "/Users/rohithbollineni/Library/Python/3.9/lib/python/site-packages/starlette/middleware/errors.py", line 164, in __call__
    await self.app(scope, receive, _send)
  File "/Users/rohithbollineni/Library/Python/3.9/lib/python/site-packages/starlette/middleware/cors.py", line 85, in __call__
    await self.app(scope, receive, send)
  File "/Users/rohithbollineni/Library/Python/3.9/lib/python/site-packages/starlette/middleware/exceptions.py", line 65, in __call__
    await wrap_app_handling_exceptions(self.app, conn)(scope, receive, send)
  File "/Users/rohithbollineni/Library/Python/3.9/lib/python/site-packages/starlette/_exception_handler.py", line 64, in wrapped_app
    raise exc
  File "/Users/rohithbollineni/Library/Python/3.9/lib/python/site-packages/starlette/_exception_handler.py", line 53, in wrapped_app
    await app(scope, receive, sender)
  File "/Users/rohithbollineni/Library/Python/3.9/lib/python/site-packages/starlette/routing.py", line 756, in __call__
    await self.middleware_stack(scope, receive, send)
  File "/Users/rohithbollineni/Library/Python/3.9/lib/python/site-packages/starlette/routing.py", line 776, in app
    await route.handle(scope, receive, send)
  File "/Users/rohithbollineni/Library/Python/3.9/lib/python/site-packages/starlette/routing.py", line 297, in handle
    await self.app(scope, receive, send)
  File "/Users/rohithbollineni/Library/Python/3.9/lib/python/site-packages/starlette/routing.py", line 77, in app
    await wrap_app_handling_exceptions(app, request)(scope, receive, send)
  File "/Users/rohithbollineni/Library/Python/3.9/lib/python/site-packages/starlette/_exception_handler.py", line 64, in wrapped_app
    raise exc
  File "/Users/rohithbollineni/Library/Python/3.9/lib/python/site-packages/starlette/_exception_handler.py", line 53, in wrapped_app
    await app(scope, receive, sender)
  File "/Users/rohithbollineni/Library/Python/3.9/lib/python/site-packages/starlette/routing.py", line 72, in app
    response = await func(request)
  File "/Users/rohithbollineni/Library/Python/3.9/lib/python/site-packages/fastapi/routing.py", line 278, in app
    raw_response = await run_endpoint_function(
  File "/Users/rohithbollineni/Library/Python/3.9/lib/python/site-packages/fastapi/routing.py", line 191, in run_endpoint_function
    return await dependant.call(**values)
  File "/Users/rohithbollineni/Downloads/Marshalats/backend/server.py", line 455, in register_user
    existing_user = await db.users.find_one({
  File "/Library/Developer/CommandLineTools/Library/Frameworks/Python3.framework/Versions/3.9/lib/python3.9/concurrent/futures/thread.py", line 52, in run
    result = self.fn(*self.args, **self.kwargs)
  File "/Users/rohithbollineni/Library/Python/3.9/lib/python/site-packages/pymongo/collection.py", line 1508, in find_one
    for result in cursor.limit(-1):
  File "/Users/rohithbollineni/Library/Python/3.9/lib/python/site-packages/pymongo/cursor.py", line 1262, in next
    if len(self.__data) or self._refresh():
  File "/Users/rohithbollineni/Library/Python/3.9/lib/python/site-packages/pymongo/cursor.py", line 1153, in _refresh
    self.__session = self.__collection.database.client._ensure_session()
  File "/Users/rohithbollineni/Library/Python/3.9/lib/python/site-packages/pymongo/mongo_client.py", line 1868, in _ensure_session
    return self.__start_session(True, causal_consistency=False)
  File "/Users/rohithbollineni/Library/Python/3.9/lib/python/site-packages/pymongo/mongo_client.py", line 1811, in __start_session
    self._topology._check_implicit_session_support()
  File "/Users/rohithbollineni/Library/Python/3.9/lib/python/site-packages/pymongo/topology.py", line 583, in _check_implicit_session_support
    self._check_session_support()
  File "/Users/rohithbollineni/Library/Python/3.9/lib/python/site-packages/pymongo/topology.py", line 599, in _check_session_support
    self._select_servers_loop(
  File "/Users/rohithbollineni/Library/Python/3.9/lib/python/site-packages/pymongo/topology.py", line 269, in _select_servers_loop
    raise ServerSelectionTimeoutError(
pymongo.errors.ServerSelectionTimeoutError: localhost:27017: [Errno 61] Connection refused, Timeout: 30s, Topology Description: <TopologyDescription id: 68b415f3e399609350ce5040, topology_type: Unknown, servers: [<ServerDescription ('localhost', 27017) server_type: Unknown, rtt: None, error=AutoReconnect('localhost:27017: [Errno 61] Connection refused')>]>
